Workbook

Sheet DIAGNOSTICO
A1: DIAGNÓSTICO — NÃO É O MASTER | B1: Anterior / Old | C1: Escalar / Scalar | D1: Igual / Equal | E1: Procedimento
A3: Valores guardados não validam o cálculo no Excel. | E3: 1. Ative edição. 2. Ctrl+Alt+F9. 3. Guarde, feche e reabra. 4. Registe que células falham.
A5: Peso total construção | B5: =SUM('V06 Motor'!G5:G184) -> 1 | C5: =SUM('V06 Motor'!H5:H184) -> 1 | D5: =ABS(B5-C5)<0.00001 -> TRUE | E5: As fórmulas antigas são cópias exatas do V06 anterior. As novas usam a mesma curva e as mesmas 94 frações, sem IF matricial/SUMPRODUCT.
A6: Recebimentos totais | B6: =SUM('V06 Motor'!O5:O184) -> 50656336 | C6: =SUM('V06 Motor'!P5:P184) -> 50656336 | D6: =ABS(B6-C6)<0.00001 -> TRUE
E7: Microsoft Excel 365: NOT TESTED neste ambiente. Este ficheiro permite isolar os dois blocos, sem carregar o master completo.
A9: Peso construção M1 | B9: ='V06 Motor'!G5 -> 0.01 | C9: ='V06 Motor'!H5 -> 0.01 | D9: =ABS(B9-C9)<0.00001 -> TRUE
A10: Recebimentos M1 | B10: ='V06 Motor'!O5 -> 2032938.9 | C10: ='V06 Motor'!P5 -> 2032938.9 | D10: =ABS(B10-C10)<0.00001 -> TRUE
A12: Não há IFERROR a ocultar erros neste diagnóstico. | E12: O diagnóstico não prova que o problema original tem esta causa; compara os blocos suspeitos em Excel nativo.

Sheet V06 Controlos
A5: Idioma | B5: PT
A6: IVA de estudo | B6: 0.15
A7: Fração recuperável IVA | B7: 1
A8: Prazo reembolso IVA | B8: 6
A9: Taxa IRPC | B9: 0.2
A10: Anos isenção simulada | B10: 0
A11: Prazo pagamento IRPC | B11: 3
A12: Base depreciável | B12: 40100000
A13: Vida útil fiscal | B13: 30
A14: Base IPI Hotel/MICE | B14: 40100000
A15: Taxa IPI | B15: 0
A16: ITI referência | B16: 0.015
A17: Fração ITI suportada KK | B17: 0
... A53: Reserva contingência jurídica HOTUSA | B53: 1000000
A54: Estado HOTUSA | B54: Pending
A55: Obrigação HOTUSA confirmada | B55: 0
A56: Mês resolução HOTUSA | B56: 180
A57: Política dividendos | B57: Auto
A58: Cobertura 12M | B58: 1.2
A59: Lucros documentados ou proxy | B59: Proxy
A60: Limite dividendos documentado | B60: 0
A61: Fração distribuição parcial | B61: 0.5
A62: Múltiplo saída | B62: 12
A63: Custo saída | B63: 0.02
A64: Mês saída | B64: 180
A65: Desconto equity | B65: 0.12
A66: Desconto projeto | B66: 0.1
A67: Cenário Hotel | B67: Favorável
A68: Fee base operador | B68: 0.03
A69: Sistemas e distribuição | B69: 0.03
A70: Fee incentivo | B70: 0.06
A71: Outros fees receita | B71: 0
A72: Yield residencial inicial | B72: 0.0425
A73: Incremento anual yield | B73: 0.0025
A74: Estado Convenção | B74: Em preparação
A75: ETC adicional | B75: 0
A76: Mês controlo obra | B76: 0
A77: Direitos aduaneiros KK | B77: 0
A78: Imposto selo KK | B78: 0
A79: Outras taxas institucionais | B79: 0
...

Sheet V06 Curva
A5: 1 | B5: 0.01
A6: 2 | B6: 0.0124
A7: 3 | B7: 0.0184
A8: 4 | B8: 0.02345
A9: 5 | B9: 0.0265
A10: 6 | B10: 0.0225
A11: 7 | B11: 0.0141
A12: 8 | B12: 0.0141
A13: 9 | B13: 0.0147
A14: 10 | B14: 0.0134
A15: 11 | B15: 0.0188
A16: 12 | B16: 0.0256
... A34: 30 | B34: 0.001

Sheet V06 Unidades
A5: 201 | H5: 552000 | I5: 1 | L5: 28
A6: 202 | H6: 402500 | I6: 1 | L6: 29
A7: 203 | H7: 253000 | I7: 1 | L7: 30
A8: 204 | H8: 253000 | I8: 1 | L8: 28
A9: 205 | H9: 402500 | I9: 1 | L9: 29
A10: 206 | H10: 408250 | I10: 1 | L10: 30
A11: 207 | H11: 253000 | I11: 1 | L11: 28
A12: 208 | H12: 253000 | I12: 1 | L12: 29
A13: 209 | H13: 402500 | I13: 4 | L13: 30
A14: 210 | H14: 552000 | I14: 4 | L14: 28
A15: 301 | H15: 563040 | I15: 4 | L15: 29
A16: 302 | H16: 410550 | I16: 4 | L16: 30
... A98: 1104 | H98: 1530100 | I98: 22 | L98: 30

Sheet V06 Calend 01
A4: Unit | B4: Price EUR | C4: Sale month | D4: Deed month | E4: Progress instalments | F4: Deposit 5% | G4: Contract 20% | H4: Progress 55% | I4: Instalment EUR | J4: Final EUR | K4: Selling costs | L4: Forecast only | M4: M001 | N4: M002 | O4: M003 | P4: M004 | Q4: M005 | R4: M006 | S4: M007 | T4: M008 | U4: M009 | V4: M010 | W4: M011 | X4: M012 | Y4: M013 | Z4: M014 | AA4: M015 | AB4: M016 | AC4: M017 | AD4: M018 | AE4: M019 | AF4: M020 | AG4: M021 | AH4: M022 | AI4: M023 | AJ4: M024 | AK4: M025 | AL4: M026 | AM4: M027 | AN4: M028 | AO4: M029 | AP4: M030 | AQ4: M031 | AR4: M032 | AS4: M033 | AT4: M034 | AU4: M035 | AV4: M036 | AW4: M037 | AX4: M038 | AY4: M039 | AZ4: M040 | BA4: M041 | BB4: M042 | BC4: M043 | BD4: M044 | BE4: M045 | BF4: M046 | BG4: M047 | BH4: M048 | BI4: M049 | BJ4: M050 | BK4: M051 | BL4: M052 | BM4: M053 | BN4: M054 | BO4: M055 | BP4: M056 | BQ4: M057 | BR4: M058 | BS4: M059 | BT4: M060 | BU4: M061 | BV4: M062 | BW4: M063 | BX4: M064 | BY4: M065 | BZ4: M066 | CA4: M067 | CB4: M068 | CC4: M069 | CD4: M070 | CE4: M071 | CF4: M072 | CG4: M073 | CH4: M074 | CI4: M075 | CJ4: M076 | CK4: M077 | CL4: M078 | CM4: M079 | CN4: M080 | CO4: M081 | CP4: M082 | CQ4: M083 | CR4: M084 | CS4: M085 | CT4: M086 | CU4: M087 | CV4: M088 | CW4: M089 | CX4: M090 | CY4: M091 | CZ4: M092 | DA4: M093 | DB4: M094 | DC4: M095 | DD4: M096 | DE4: M097 | DF4: M098 | DG4: M099 | DH4: M100 | DI4: M101 | DJ4: M102 | DK4: M103 | DL4: M104 | DM4: M105 | DN4: M106 | DO4: M107 | DP4: M108 | DQ4: M109 | DR4: M110 | DS4: M111 | DT4: M112 | DU4: M113 | DV4: M114 | DW4: M115 | DX4: M116 | DY4: M117 | DZ4: M118 | EA4: M119 | EB4: M120 | EC4: M121 | ED4: M122 | EE4: M123 | EF4: M124 | EG4: M125 | EH4: M126 | EI4: M127 | EJ4: M128 | EK4: M129 | EL4: M130 | EM4: M131 | EN4: M132 | EO4: M133 | EP4: M134 | EQ4: M135 | ER4: M136 | ES4: M137 | ET4: M138 | EU4: M139 | EV4: M140 | EW4: M141 | EX4: M142 | EY4: M143 | EZ4: M144 | FA4: M145 | FB4: M146 | FC4: M147 | FD4: M148 | FE4: M149 | FF4: M150 | FG4: M151 | FH4: M152 | FI4: M153 | FJ4: M154 | FK4: M155 | FL4: M156 | FM4: M157 | FN4: M158 | FO4: M159 | FP4: M160 | FQ4: M161 | FR4: M162 | FS4: M163 | FT4: M164 | FU4: M165 | FV4: M166 | FW4: M167 | FX4: M168 | FY4: M169 | FZ4: M170 | GA4: M171 | GB4: M172 | GC4: M173 | GD4: M174 | GE4: M175 | GF4: M176 | GG4: M177 | GH4: M178 | GI4: M179 | GJ4: M180
